Workbook

Sheet 指令生成器
B1: 快手广告创建 - 指令参数模板
B2: 蓝色=每次修改 | 灰色=固定 | 黄色=下拉选 | 橙色=自动生成指令
B4: 参数设置
B5: 参数名 | C5: 参数值 | D5: 快捷选择 ▼ | E5: 说明
B6: 基建组数 | C6: 100 | D6: 手动填写 | E6: 建多少组广告
B7: 账户ID | D7: 手动填写 | E7: 快手广告主账户ID
B8: 任务ID | C8: =IF(D8="— 选择任务 —","",IF(D8="",C8,IFERROR(VLOOKUP(D8,常用配置库!$C$60:$D$93,2,FALSE),""))) | D8: — 选择任务 — | E8: 下拉选任务名称自动填入
B9: 素材套餐 | C9: =IF(D9="— 选择素材 —","",D9) | D9: — 选择素材 — | E9: 选模板→素材库/落地页/文案一起填
B10: 素材库ID | C10: =IF(D9="— 选择素材 —","",IFERROR(VLOOKUP(D9,常用配置库!$B$5:$E$20,2,FALSE),"")) | D10: 自动填入 | E10: ← 自动
B11: 落地页 | C11: =IF(D9="— 选择素材 —","",IFERROR(VLOOKUP(D9,常用配置库!$B$5:$E$20,3,FALSE),"")) | D11: 自动填入 | E11: ← 自动
B12: 文案库ID | C12: =IF(D9="— 选择素材 —","",IFERROR(VLOOKUP(D9,常用配置库!$B$5:$E$20,4,FALSE),"")) | D12: 自动填入 | E12: ← 自动
B13: 参考套餐 | C13: =IF(D13="— 选择套餐 —","",D13) | D13: — 选择套餐 — | E13: 选昵称→账户/计划/组一起填
B14: 参考账户ID | C14: =IF(D13="— 选择套餐 —","",IFERROR(VLOOKUP(D13,常用配置库!$B$24:$E$47,2,FALSE),"")) | D14: 自动填入 | E14: ← 自动
B15: 参考计划ID | C15: =IF(D13="— 选择套餐 —","",IFERROR(VLOOKUP(D13,常用配置库!$B$24:$E$47,3,FALSE),"")) | D15: 自动填入 | E15: ← 自动
B16: 参考广告组ID | C16: =IF(D13="— 选择套餐 —","",IFERROR(VLOOKUP(D13,常用配置库!$B$24:$E$47,4,FALSE),"")) | D16: 自动填入 | E16: ← 自动
B17: 出价方式 | C17: =D17 | D17: 付费 | E17: 付费/订单/激活
B18: 出价金额 | D18: 手动填写 | E18: 单位：元
B19: 伪装参数 | C19: =IF(D19="— 选择 —","",IF(D19="",C19,D19)) | D19: — 选择 — | E19: 激活出价时选，完整值直接填入
B20: 设备类型 | C20: =D20 | D20: 双端设备 | E20: 双端设备/iOS/Android
B21: 过滤已安装 | C21: =D21 | D21: 过滤 | E21: 过滤/不过滤
B22: 投放时段 | C22: =IF(D22="— 选择时段 —","",IFERROR(VLOOKUP(D22,常用配置库!$B$87:$C$101,2,FALSE),"")) | D22: — 选择时段 — | E22: 下拉选时段模板
B24: 资源位选择（可多选）
B25: 资源位名称 | D25: 是否启用 ▼ | E25: 说明 | G25: =IF(D26="是","优选,","")&IF(D27="是","上下滑,","")&IF(D28="是","激励,","")&IF(D29="是","联盟,","")&IF(D30="是","开屏,","")
B26: 优选 | D26: 是 | E26: 系统自动优选
B27: 上下滑 | D27: 否 | E27: 信息流上下滑
B28: 激励 | D28: 否 | E28: 激励视频
B29: 联盟 | D29: 否 | E29: 联盟流量
B30: 开屏 | D30: 否 | E30: 开屏广告
B32: 固定参数
B33: 参数名 | C33: 参数值 | E33: 说明
B34: 基建工具 | C34: ks-create-ad-script | E34: 固定使用此工具
B36: 自动生成的完整指令（直接复制使用）
B37: ="使用ks-create-ad-script基建"&C6&"组快手广告，"&"账户ID为"&C7&"，任务ID "&C8&"，"&IF(C14<>"","参考"&C14&"账户原来的计划"&C15&IF(C16<>"","组"&C16,"")&"，","")&"出价方式"&C17&IF(C18<>"","，出价"&C18&"元","")&"，"&"素材库"&C10&"，落地页"&C11&"，文案库"&C12&"，"&C20&"，"&IF(G25<>"",LEFT(G25,LEN(G25)-1),"")&"资源位，"&C21&"，投放时段"&C22&"点"&IF(C19<>"","，"&C19,"")&"，其他默认"
B39: 指令效果预览（示例）
B40: 使用ks-create-ad-script基建100组快手广告，账户ID为xxx，任务ID 1803240580，参考1803240580账户原来的计划979504组222，出价方式激活，出价30元，素材库81395，落地页landing_v2_1388，文案库431，双端设备，优选资源位，过滤，投放时段7-22点，&translationTag=86_60&translationTag2=104_60，其他默认
B42: 使用说明
B43: 1. 基建组数：填要建多少组广告，如100
B44: 2. 任务ID：下拉选任务名称 → 任务ID自动填入
B45: 3. 素材套餐：下拉选模板名 → 素材库ID/落地页/文案库ID 三个一起填
B46: 4. 参考套餐：下拉选昵称 → 参考账户ID/计划ID/广告组ID 三个一起填
...

Sheet 批量创建模板
A1: 快手广告批量创建 - 每行一条广告
A2: W列自动生成指令，直接复制使用
A4: 序号 | B4: 组数 | C4: 账户ID | D4: 任务ID | E4: 参考账户ID | F4: 参考计划ID | G4: 参考广告组ID | H4: 出价方式 | I4: 出价(元) | J4: 伪装参数 | K4: 素材库ID | L4: 落地页 | M4: 文案库ID | N4: 设备类型 | O4: 过滤已安装 | P4: 投放时段 | Q4: 优选 | R4: 上下滑 | S4: 激励 | T4: 联盟 | U4: 开屏 | W4: 自动生成指令
A5: 1 | B5: 100 | H5: 付费 | K5: 81395 | L5: landing_v2_1388 | M5: 431 | N5: 双端设备 | O5: 过滤 | P5: 7-22 | Q5: 是 | R5: 否 | S5: 否 | T5: 否 | U5: 否 | V5: =IF(Q5="是","优选,","")&IF(R5="是","上下滑,","")&IF(S5="是","激励,","")&IF(T5="是","联盟,","")&IF(U5="是","开屏,","") | W5: ="使用ks-create-ad-script基建"&B5&"组快手广告，"&"账户ID为"&C5&"，任务ID "&D5&"，"&IF(E5<>"","参考"&E5&"账户原来的计划"&F5&IF(G5<>"","组"&G5,"")&"，","")&"出价方式"&H5&IF(I5<>"","，出价"&I5&"元","")&"，"&"素材库"&K5&"，落地页"&L5&"，文案库"&M5&"，"&N5&"，"&IF(V5<>"",LEFT(V5,LEN(V5)-1),"")&"资源位，"&O5&"，投放时段"&P5&"点"&IF(J5<>"","，"&J5,"")&"，其他默认"
A6: 2 | B6: 100 | H6: 付费 | K6: 81395 | L6: landing_v2_1388 | M6: 431 | N6: 双端设备 | O6: 过滤 | P6: 7-22 | Q6: 是 | R6: 否 | S6: 否 | T6: 否 | U6: 否 | V6: =IF(Q6="是","优选,","")&IF(R6="是","上下滑,","")&IF(S6="是","激励,","")&IF(T6="是","联盟,","")&IF(U6="是","开屏,","") | W6: ="使用ks-create-ad-script基建"&B6&"组快手广告，"&"账户ID为"&C6&"，任务ID "&D6&"，"&IF(E6<>"","参考"&E6&"账户原来的计划"&F6&IF(G6<>"","组"&G6,"")&"，","")&"出价方式"&H6&IF(I6<>"","，出价"&I6&"元","")&"，"&"素材库"&K6&"，落地页"&L6&"，文案库"&M6&"，"&N6&"，"&IF(V6<>"",LEFT(V6,LEN(V6)-1),"")&"资源位，"&O6&"，投放时段"&P6&"点"&IF(J6<>"","，"&J6,"")&"，其他默认"
A7: 3 | B7: 100 | H7: 付费 | K7: 81395 | L7: landing_v2_1388 | M7: 431 | N7: 双端设备 | O7: 过滤 | P7: 7-22 | Q7: 是 | R7: 否 | S7: 否 | T7: 否 | U7: 否 | V7: =IF(Q7="是","优选,","")&IF(R7="是","上下滑,","")&IF(S7="是","激励,","")&IF(T7="是","联盟,","")&IF(U7="是","开屏,","") | W7: ="使用ks-create-ad-script基建"&B7&"组快手广告，"&"账户ID为"&C7&"，任务ID "&D7&"，"&IF(E7<>"","参考"&E7&"账户原来的计划"&F7&IF(G7<>"","组"&G7,"")&"，","")&"出价方式"&H7&IF(I7<>"","，出价"&I7&"元","")&"，"&"素材库"&K7&"，落地页"&L7&"，文案库"&M7&"，"&N7&"，"&IF(V7<>"",LEFT(V7,LEN(V7)-1),"")&"资源位，"&O7&"，投放时段"&P7&"点"&IF(J7<>"","，"&J7,"")&"，其他默认"
A8: 4 | B8: 100 | H8: 付费 | K8: 81395 | L8: landing_v2_1388 | M8: 431 | N8: 双端设备 | O8: 过滤 | P8: 7-22 | Q8: 是 | R8: 否 | S8: 否 | T8: 否 | U8: 否 | V8: =IF(Q8="是","优选,","")&IF(R8="是","上下滑,","")&IF(S8="是","激励,","")&IF(T8="是","联盟,","")&IF(U8="是","开屏,","") | W8: ="使用ks-create-ad-script基建"&B8&"组快手广告，"&"账户ID为"&C8&"，任务ID "&D8&"，"&IF(E8<>"","参考"&E8&"账户原来的计划"&F8&IF(G8<>"","组"&G8,"")&"，","")&"出价方式"&H8&IF(I8<>"","，出价"&I8&"元","")&"，"&"素材库"&K8&"，落地页"&L8&"，文案库"&M8&"，"&N8&"，"&IF(V8<>"",LEFT(V8,LEN(V8)-1),"")&"资源位，"&O8&"，投放时段"&P8&"点"&IF(J8<>"","，"&J8,"")&"，其他默认"
A9: 5 | B9: 100 | H9: 付费 | K9: 81395 | L9: landing_v2_1388 | M9: 431 | N9: 双端设备 | O9: 过滤 | P9: 7-22 | Q9: 是 | R9: 否 | S9: 否 | T9: 否 | U9: 否 | V9: =IF(Q9="是","优选,","")&IF(R9="是","上下滑,","")&IF(S9="是","激励,","")&IF(T9="是","联盟,","")&IF(U9="是","开屏,","") | W9: ="使用ks-create-ad-script基建"&B9&"组快手广告，"&"账户ID为"&C9&"，任务ID "&D9&"，"&IF(E9<>"","参考"&E9&"账户原来的计划"&F9&IF(G9<>"","组"&G9,"")&"，","")&"出价方式"&H9&IF(I9<>"","，出价"&I9&"元","")&"，"&"素材库"&K9&"，落地页"&L9&"，文案库"&M9&"，"&N9&"，"&IF(V9<>"",LEFT(V9,LEN(V9)-1),"")&"资源位，"&O9&"，投放时段"&P9&"点"&IF(J9<>"","，"&J9,"")&"，其他默认"
A10: 6 | B10: 100 | H10: 付费 | K10: 81395 | L10: landing_v2_1388 | M10: 431 | N10: 双端设备 | O10: 过滤 | P10: 7-22 | Q10: 是 | R10: 否 | S10: 否 | T10: 否 | U10: 否 | V10: =IF(Q10="是","优选,","")&IF(R10="是","上下滑,","")&IF(S10="是","激励,","")&IF(T10="是","联盟,","")&IF(U10="是","开屏,","") | W10: ="使用ks-create-ad-script基建"&B10&"组快手广告，"&"账户ID为"&C10&"，任务ID "&D10&"，"&IF(E10<>"","参考"&E10&"账户原来的计划"&F10&IF(G10<>"","组"&G10,"")&"，","")&"出价方式"&H10&IF(I10<>"","，出价"&I10&"元","")&"，"&"素材库"&K10&"，落地页"&L10&"，文案库"&M10&"，"&N10&"，"&IF(V10<>"",LEFT(V10,LEN(V10)-1),"")&"资源位，"&O10&"，投放时段"&P10&"点"&IF(J10<>"","，"&J10,"")&"，其他默认"
A11: 7 | B11: 100 | H11: 付费 | K11: 81395 | L11: landing_v2_1388 | M11: 431 | N11: 双端设备 | O11: 过滤 | P11: 7-22 | Q11: 是 | R11: 否 | S11: 否 | T11: 否 | U11: 否 | V11: =IF(Q11="是","优选,","")&IF(R11="是","上下滑,","")&IF(S11="是","激励,","")&IF(T11="是","联盟,","")&IF(U11="是","开屏,","") | W11: ="使用ks-create-ad-script基建"&B11&"组快手广告，"&"账户ID为"&C11&"，任务ID "&D11&"，"&IF(E11<>"","参考"&E11&"账户原来的计划"&F11&IF(G11<>"","组"&G11,"")&"，","")&"出价方式"&H11&IF(I11<>"","，出价"&I11&"元","")&"，"&"素材库"&K11&"，落地页"&L11&"，文案库"&M11&"，"&N11&"，"&IF(V11<>"",LEFT(V11,LEN(V11)-1),"")&"资源位，"&O11&"，投放时段"&P11&"点"&IF(J11<>"","，"&J11,"")&"，其他默认"
A12: 8 | B12: 100 | H12: 付费 | K12: 81395 | L12: landing_v2_1388 | M12: 431 | N12: 双端设备 | O12: 过滤 | P12: 7-22 | Q12: 是 | R12: 否 | S12: 否 | T12: 否 | U12: 否 | V12: =IF(Q12="是","优选,","")&IF(R12="是","上下滑,","")&IF(S12="是","激励,","")&IF(T12="是","联盟,","")&IF(U12="是","开屏,","") | W12: ="使用ks-create-ad-script基建"&B12&"组快手广告，"&"账户ID为"&C12&"，任务ID "&D12&"，"&IF(E12<>"","参考"&E12&"账户原来的计划"&F12&IF(G12<>"","组"&G12,"")&"，","")&"出价方式"&H12&IF(I12<>"","，出价"&I12&"元","")&"，"&"素材库"&K12&"，落地页"&L12&"，文案库"&M12&"，"&N12&"，"&IF(V12<>"",LEFT(V12,LEN(V12)-1),"")&"资源位，"&O12&"，投放时段"&P12&"点"&IF(J12<>"","，"&J12,"")&"，其他默认"
A13: 9 | B13: 100 | H13: 付费 | K13: 81395 | L13: landing_v2_1388 | M13: 431 | N13: 双端设备 | O13: 过滤 | P13: 7-22 | Q13: 是 | R13: 否 | S13: 否 | T13: 否 | U13: 否 | V13: =IF(Q13="是","优选,","")&IF(R13="是","上下滑,","")&IF(S13="是","激励,","")&IF(T13="是","联盟,","")&IF(U13="是","开屏,","") | W13: ="使用ks-create-ad-script基建"&B13&"组快手广告，"&"账户ID为"&C13&"，任务ID "&D13&"，"&IF(E13<>"","参考"&E13&"账户原来的计划"&F13&IF(G13<>"","组"&G13,"")&"，","")&"出价方式"&H13&IF(I13<>"","，出价"&I13&"元","")&"，"&"素材库"&K13&"，落地页"&L13&"，文案库"&M13&"，"&N13&"，"&IF(V13<>"",LEFT(V13,LEN(V13)-1),"")&"资源位，"&O13&"，投放时段"&P13&"点"&IF(J13<>"","，"&J13,"")&"，其他默认"
A14: 10 | B14: 100 | H14: 付费 | K14: 81395 | L14: landing_v2_1388 | M14: 431 | N14: 双端设备 | O14: 过滤 | P14: 7-22 | Q14: 是 | R14: 否 | S14: 否 | T14: 否 | U14: 否 | V14: =IF(Q14="是","优选,","")&IF(R14="是","上下滑,","")&IF(S14="是","激励,","")&IF(T14="是","联盟,","")&IF(U14="是","开屏,","") | W14: ="使用ks-create-ad-script基建"&B14&"组快手广告，"&"账户ID为"&C14&"，任务ID "&D14&"，"&IF(E14<>"","参考"&E14&"账户原来的计划"&F14&IF(G14<>"","组"&G14,"")&"，","")&"出价方式"&H14&IF(I14<>"","，出价"&I14&"元","")&"，"&"素材库"&K14&"，落地页"&L14&"，文案库"&M14&"，"&N14&"，"&IF(V14<>"",LEFT(V14,LEN(V14)-1),"")&"资源位，"&O14&"，投放时段"&P14&"点"&IF(J14<>"","，"&J14,"")&"，其他默认"
A15: 11 | B15: 100 | H15: 付费 | K15: 81395 | L15: landing_v2_1388 | M15: 431 | N15: 双端设备 | O15: 过滤 | P15: 7-22 | Q15: 是 | R15: 否 | S15: 否 | T15: 否 | U15: 否 | V15: =IF(Q15="是","优选,","")&IF(R15="是","上下滑,","")&IF(S15="是","激励,","")&IF(T15="是","联盟,","")&IF(U15="是","开屏,","") | W15: ="使用ks-create-ad-script基建"&B15&"组快手广告，"&"账户ID为"&C15&"，任务ID "&D15&"，"&IF(E15<>"","参考"&E15&"账户原来的计划"&F15&IF(G15<>"","组"&G15,"")&"，","")&"出价方式"&H15&IF(I15<>"","，出价"&I15&"元","")&"，"&"素材库"&K15&"，落地页"&L15&"，文案库"&M15&"，"&N15&"，"&IF(V15<>"",LEFT(V15,LEN(V15)-1),"")&"资源位，"&O15&"，投放时段"&P15&"点"&IF(J15<>"","，"&J15,"")&"，其他默认"
A16: 12 | B16: 100 | H16: 付费 | K16: 81395 | L16: landing_v2_1388 | M16: 431 | N16: 双端设备 | O16: 过滤 | P16: 7-22 | Q16: 是 | R16: 否 | S16: 否 | T16: 否 | U16: 否 | V16: =IF(Q16="是","优选,","")&IF(R16="是","上下滑,","")&IF(S16="是","激励,","")&IF(T16="是","联盟,","")&IF(U16="是","开屏,","") | W16: ="使用ks-create-ad-script基建"&B16&"组快手广告，"&"账户ID为"&C16&"，任务ID "&D16&"，"&IF(E16<>"","参考"&E16&"账户原来的计划"&F16&IF(G16<>"","组"&G16,"")&"，","")&"出价方式"&H16&IF(I16<>"","，出价"&I16&"元","")&"，"&"素材库"&K16&"，落地页"&L16&"，文案库"&M16&"，"&N16&"，"&IF(V16<>"",LEFT(V16,LEN(V16)-1),"")&"资源位，"&O16&"，投放时段"&P16&"点"&IF(J16<>"","，"&J16,"")&"，其他默认"
... A24: 20 | B24: 100 | H24: 付费 | K24: 81395 | L24: landing_v2_1388 | M24: 431 | N24: 双端设备 | O24: 过滤 | P24: 7-22 | Q24: 是 | R24: 否 | S24: 否 | T24: 否 | U24: 否 | V24: =IF(Q24="是","优选,","")&IF(R24="是","上下滑,","")&IF(S24="是","激励,","")&IF(T24="是","联盟,","")&IF(U24="是","开屏,","") | W24: ="使用ks-create-ad-script基建"&B24&"组快手广告，"&"账户ID为"&C24&"，任务ID "&D24&"，"&IF(E24<>"","参考"&E24&"账户原来的计划"&F24&IF(G24<>"","组"&G24,"")&"，","")&"出价方式"&H24&IF(I24<>"","，出价"&I24&"元","")&"，"&"素材库"&K24&"，落地页"&L24&"，文案库"&M24&"，"&N24&"，"&IF(V24<>"",LEFT(V24,LEN(V24)-1),"")&"资源位，"&O24&"，投放时段"&P24&"点"&IF(J24<>"","，"&J24,"")&"，其他默认"

Sheet 常用配置库
A1: 常用配置库 - 所有下拉值在这里维护
B3: 1. 素材模板
B4: 模板名称 | C4: 素材库ID | D4: 落地页 | E4: 文案库ID
B5: 素材-标准版 | C5: 81395 | D5: landing_v2_1388 | E5: 431
B22: 2. 参考账户模板（选昵称→账户ID/计划ID/组ID一起填入）
B23: 套餐昵称 | C23: 参考账户ID | D23: 参考计划ID | E23: 参考广告组ID
B24: 闪购-标准定向 | C24: 523782219
B25: 闪购-MAC定向 | C25: 463096449
B26: aac-CVR有端套餐 | C26: 1803240580
B27: aac-CVR排除套餐 | C27: 1393509178
B28: CVR-商详套餐 | C28: 1528775666
B29: CVR-达人二创套餐 | C29: 58739616
B30: 闲鱼-DAU套餐 | C30: 1278297263
B31: 促活UV-标准套餐 | C31: 630935345
B42: 3. 伪装参数（激活出价时选，写啥用啥不拆分）
B43: 说明 | C43: 伪装参数值（完整值）
B44: CVR/aac 专用 | C44: &translationTag=86_60&translationTag2=104_60
B45: 闪购专用 | C45: &translationTag2=143_60
B58: 4. 任务模板
B59: 业务线 | C59: 任务名称 | D59: 任务ID
B60: 闪购 | C60: 闪购MAC直营 | D60: 523782219
B61: 闪购 | C61: 闪购MAC | D61: 463096449
B62: 闪购 | C62: M闪购排除 | D62: 703153690
B63: 闪购 | C63: M闪购无端 | D63: 2056078744
B64: aac | C64: CVR有端① | D64: 1803240580
B65: aac | C65: CVR排除① | D65: 1393509178
B66: aac | C66: CVR无端 | D66: 1578323710
B67: aac | C67: CVR排除② | D67: 219955634
B68: aac | C68: CVR有端② | D68: 302271253
B69: aac | C69: CVR有端③ | D69: 1608075348
B70: aac | C70: CVR排除IOS | D70: 245189750
... B82: 促活UV | C82: 促活UV④ | D82: 1488406551
B85: 5. 时段模板
B86: 模板名称 | C86: 时段值
B87: 白天投放 | C87: 7-22
B88: 全天投放 | C88: 0-24
B89: 夜间投放 | C89: 20-6
B90: 黄金时段 | C90: 10-14,18-22
